Workbook
Name Anniversaire: TAM!$B$27:$F$27,TAM!$B$39:$F$39,TAM!$B$51:$F$51,TAM!$B$63:$F$63
Name CAP1E: TAM!$S$6
Name CapitFIXE: TAM!#REF!
Name Changement_de_taux: TAM!$B$15:$B$315
Name Cout_Total: TAM!$P$8
Name DATDB: TAM!$S$7
Name DebAmort: TAM!$F$6
Name Différé: TAM!$V$8
Name DiffSimple: TAM!$V$6
Name DiffTotal: TAM!$V$7
Name EchFIXE: TAM!$S$2
Name FraisF: TAM!$M$3
Name FraisV: TAM!$M$4
Name Ijour: TAM!$T$6
Name Imois: TAM!$T$5
Name INT1E: TAM!$S$5
Name Jour1: TAM!$T$7
Name Jour2: TAM!$T$8
Name MoisD: TAM!$T$9
Name MtEch: TAM!$D$8
Name MtEmprunt: TAM!$V$12
Name NbDeci: TAM!$S$1
Name NbEch: TAM!$T$2
Name NbEchAn: TAM!$T$1
Name NoEchMaxi: TAM!$S$3
Name NoEchRemb: TAM!$S$4
Name Nombre_échéances: TAM!$P$4
Name Periodicite: TAM!$W$10
Name RVDebit: TAM!#REF!
Name TauxActuariel: TAM!$V$3
Name Total_Capital: TAM!$P$6
Name Total_Frais: TAM!$P$7
Name Total_Intérêts: TAM!$P$5
Name TVDebit: TAM!$B$2:$B$8
Name TxPer: TAM!$T$4

Sheet TAM
S1: =IF(ISERROR(Avancé!D3),2,Avancé!D3) | T1: =IF(Periodicite="M",12)+IF(Periodicite="T",4)+IF(Periodicite="S",2)+IF(Periodicite="A",1)+IF(Periodicite="H",52)+IF(Periodicite="Q",26)+IF(Periodicite="B",24) | U1: Nombre échéance par an | V1: Type Taux | W1: Periodicité
B2: Caractéristiques | K2: Frais | N2: Récapitulatif | S2: =IF(ISERROR(Avancé!I9),TRUE,IF(Avancé!I9=1,TRUE,FALSE)) | T2: =T3*NbEchAn/12 | U2: Nombre échéance total | V2: 2 | W2: 1
C3: Montant emprunté : | D3: 80000 | E3: durée : | F3: 15 | G3: ans | K3: Frais Fixe (ADI) / ech | N3: Date dernière échéance | P3: =MAX(K14:K447) | S3: =IF(ISERROR(Avancé!D17),99999,Avancé!D17) | T3: =F3*12+F4 | U3: Durée totale (en mois) | V3: =V2=1 | W3: Mensuel
E4: et | F4: 11 | G4: mois | K4: Frais variable (en %CRD) | N4: Nombre échéances | P4: =MAX(H14:H447) | S4: =IF(ISERROR(Avancé!E17),99999,Avancé!E17) | T4: =IF(TauxActuariel,((D5+1)^(1/NbEchAn))-1,D5/NbEchAn) | U4: Taux période | V4: Différé | W4: Trimestriel
C5: Taux annuel : | D5: 0.1 | F5: 1° échéance : | H5: Périodicité : | K5: Différé | N5: Total Intérêts | P5: =SUM(M14:M447) | S5: =IF(1<=NoEchMaxi, IF(ISERROR(Avancé!D37),ROUND(L15*R15,NbDeci),Avancé!D37), 0) | T5: =0+IF(Periodicite="M",1)+IF(Periodicite="T",3)+IF(Periodicite="S",6)+IF(Periodicite="A",12)+IF(Periodicite="B",0.5) | U5: IntervalMois | V5: 1 | W5: Semestriel
F6: 46128 | N6: Total Capital | P6: =SUM(N14:N447)-SUMIF(C14:C447,"<0") | S6: =IF(1>NoEchMaxi, 0, IF(ISERROR(Avancé!E37), IF(1<=Différé,IF(DiffTotal,-INT1E,0),IF(1>=NoEchRemb,L15,IF(S15-(M15*EchFIXE)>L15-2,L15,S15-(M15*EchFIXE))))+C15, Avancé!E37)) | T6: =0+IF(Periodicite="H",7)+IF(Periodicite="Q",14) | U6: IntervalJour | V6: =IF(Différé>0,V5=1,FALSE) | W6: Annuel
K7: Nombre de mois différé | M7: 0 | N7: Total Frais | P7: =SUM(O14:O447) | S7: =IF(ISERROR(Avancé!C37), IF(Ijour=0,MIN(DATE(YEAR(DebAmort),MONTH(DebAmort)-MoisD-Imois,Jour2),DATE(YEAR(DebAmort),MONTH(DebAmort)-MoisD+1-Imois,0)),DATE(YEAR(DebAmort),MONTH(DebAmort),Jour1-Ijour)), Avancé!C37) | T7: =DAY(DebAmort) | U7: J1 | V7: =IF(Différé>0,V5=2,FALSE) | W7: Hebdomadaire
C8: =IF(EchFIXE,"Montant échéance fixe :","Capital / échéance :") | D8: =IF(OR(D5=0,NOT(EchFIXE)),ROUND(MtEmprunt/NbEch,NbDeci),ROUND(MtEmprunt*TxPer/(1-((1+TxPer)^-NbEch)),NbDeci)) | K8: Déblocage initial | N8: Coût total crédit | P8: =SUM(P5:P7) | T8: =IF(Periodicite="B",IF(T7>15,MIN(T7-15,15),T7+15),T7) | U8: J2 | V8: =M7*NbEchAn/12 | W8: Quinzaine
T9: =IF(Jour2<Jour1,1,0) | U9: M1 | V9: MtEmprunt | W9: Bimensuel
B10: Opération | H10: Tableau d'amortissement | R10: Données recalcul | V10: =D3 | W10: =UPPER(LEFT(INDEX(W3:W9,W2,1)))
B11: =COUNTIF(B15:B447,">0") | C11: =COUNTIF(C15:C447,">0")+COUNTIF(C15:C447,"<0") | D11: =COUNTIF(D15:D447,">0") | E11: =COUNTIF(E15:E447,">0") | F11: =COUNTIF(F14:F447,">0") | I11: Reste sur initial | K11: Date Échéance | L11: Capital restant dû | M11: Intérêts payés | N11: Capital remboursé | O11: Montant des Frais | P11: Total payé | R11: Taux période | S11: Montant échéance | V11: =INDEX(L15:L996,Différé+1,1)
B12: Nouveau Taux | C12: Capital remboursé | D12: Nouveau Nb d'échéance | E12: Nouvelle échéance | F12: Frais opération | H12: N° | J12: Année | V12: =IF(DiffTotal,V11,V10)
H13: Ech
C14: =IF(M8>0,-M8,-D3) | D14: Déblocage initial | H14: 0 | J14: =IF(ISNUMBER(K14),YEAR(K14),"") | K14: =DATDB | L14: 0 | N14: =C14 | O14: =F14 | P14: =SUM(M14:O14)
H15: =IF(L15=0,"",H14+1) | I15: =IF(L15>0,NbEch+Différé+1-H15,"") | J15: =IF(ISNUMBER(K15),YEAR(K15),"") | K15: =DATE(YEAR(DebAmort),MONTH(DebAmort),DAY(DebAmort)) | L15: =L14-N14 | M15: =INT1E | N15: =CAP1E+C15 | O15: =IF(OR(L15=0,H15>NoEchMaxi),0,ROUND(FraisF+FraisV*L15,NbDeci))+F15 | P15: =SUM(M15:O15) | R15: =IF(B15>0,IF(TauxActuariel,((B15+1)^(1/NbEchAn))-1,B15/NbEchAn),TxPer) | S15: =IF(E15>0,E15,IF(D15>0,IF(AND(EchFIXE,R15>0),ROUND((L15-C15)*R15/(1-((1+R15)^-D15)),NbDeci),ROUND(L15/D15,NbDeci)),MtEch))
H16: =IF(L16=0,"",H15+1) | I16: =IF(L16>0,NbEch+Différé+1-H16,"") | J16: =IF(ISNUMBER(K16),YEAR(K16),"") | K16: =IF(L16=0,"",IF(Ijour=0,MIN(DATE(YEAR(DebAmort),MONTH(DebAmort)+MoisD+(H16-1)*Imois,Jour2),DATE(YEAR(DebAmort),MONTH(DebAmort)+MoisD+1+(H16-1)*Imois,0)),DATE(YEAR(DebAmort),MONTH(DebAmort),Jour1+(H16-1)*Ijour))) | L16: =L15-N15 | M16: =IF(H16<=NoEchMaxi,ROUND(L16*R16,NbDeci),0) | N16: =IF(OR(H16<=Différé,H16>NoEchMaxi),IF(DiffTotal,-M16,0),IF(H16>=NoEchRemb,L16,IF(S16-(M16*EchFIXE)>L16-2,L16,S16-(M16*EchFIXE))))+C16 | O16: =IF(OR(L16=0,H16>NoEchMaxi),0,ROUND(FraisF+FraisV*L16,NbDeci))+F16 | P16: =SUM(M16:O16) | R16: =IF(B16>0,IF(TauxActuariel,((B16+1)^(1/NbEchAn))-1,B16/NbEchAn),R15) | S16: =IF(E16>0,E16,IF(D16>0,IF(AND(EchFIXE,R16>0),ROUND((L16-C16)*R16/(1-((1+R16)^-D16)),NbDeci),ROUND(L16/D16,NbDeci)),S15))
H17: =IF(L17=0,"",H16+1) | I17: =IF(L17>0,NbEch+Différé+1-H17,"") | J17: =IF(ISNUMBER(K17),YEAR(K17),"") | K17: =IF(L17=0,"",IF(Ijour=0,MIN(DATE(YEAR(DebAmort),MONTH(DebAmort)+(H17-1)*Imois,Jour1),DATE(YEAR(DebAmort),MONTH(DebAmort)+1+(H17-1)*Imois,0)),DATE(YEAR(DebAmort),MONTH(DebAmort),Jour1+(H17-1)*Ijour))) | L17: =L16-N16 | M17: =IF(H17<=NoEchMaxi,ROUND(L17*R17,NbDeci),0) | N17: =IF(OR(H17<=Différé,H17>NoEchMaxi),IF(DiffTotal,-M17,0),IF(H17>=NoEchRemb,L17,IF(S17-(M17*EchFIXE)>L17-2,L17,S17-(M17*EchFIXE))))+C17 | O17: =IF(OR(L17=0,H17>NoEchMaxi),0,ROUND(FraisF+FraisV*L17,NbDeci))+F17 | P17: =SUM(M17:O17) | R17: =IF(B17>0,IF(TauxActuariel,((B17+1)^(1/NbEchAn))-1,B17/NbEchAn),R16) | S17: =IF(E17>0,E17,IF(D17>0,IF(AND(EchFIXE,R17>0),ROUND((L17-C17)*R17/(1-((1+R17)^-D17)),NbDeci),ROUND(L17/D17,NbDeci)),S16))
H18: =IF(L18=0,"",H17+1) | I18: =IF(L18>0,NbEch+Différé+1-H18,"") | J18: =IF(ISNUMBER(K18),YEAR(K18),"") | K18: =IF(L18=0,"",IF(Ijour=0,MIN(DATE(YEAR(DebAmort),MONTH(DebAmort)+MoisD+(H18-1)*Imois,Jour2),DATE(YEAR(DebAmort),MONTH(DebAmort)+MoisD+1+(H18-1)*Imois,0)),DATE(YEAR(DebAmort),MONTH(DebAmort),Jour1+(H18-1)*Ijour))) | L18: =L17-N17 | M18: =IF(H18<=NoEchMaxi,ROUND(L18*R18,NbDeci),0) | N18: =IF(OR(H18<=Différé,H18>NoEchMaxi),IF(DiffTotal,-M18,0),IF(H18>=NoEchRemb,L18,IF(S18-(M18*EchFIXE)>L18-2,L18,S18-(M18*EchFIXE))))+C18 | O18: =IF(OR(L18=0,H18>NoEchMaxi),0,ROUND(FraisF+FraisV*L18,NbDeci))+F18 | P18: =SUM(M18:O18) | R18: =IF(B18>0,IF(TauxActuariel,((B18+1)^(1/NbEchAn))-1,B18/NbEchAn),R17) | S18: =IF(E18>0,E18,IF(D18>0,IF(AND(EchFIXE,R18>0),ROUND((L18-C18)*R18/(1-((1+R18)^-D18)),NbDeci),ROUND(L18/D18,NbDeci)),S17))
H19: =IF(L19=0,"",H18+1) | I19: =IF(L19>0,NbEch+Différé+1-H19,"") | J19: =IF(ISNUMBER(K19),YEAR(K19),"") | K19: =IF(L19=0,"",IF(Ijour=0,MIN(DATE(YEAR(DebAmort),MONTH(DebAmort)+(H19-1)*Imois,Jour1),DATE(YEAR(DebAmort),MONTH(DebAmort)+1+(H19-1)*Imois,0)),DATE(YEAR(DebAmort),MONTH(DebAmort),Jour1+(H19-1)*Ijour))) | L19: =L18-N18 | M19: =IF(H19<=NoEchMaxi,ROUND(L19*R19,NbDeci),0) | N19: =IF(OR(H19<=Différé,H19>NoEchMaxi),IF(DiffTotal,-M19,0),IF(H19>=NoEchRemb,L19,IF(S19-(M19*EchFIXE)>L19-2,L19,S19-(M19*EchFIXE))))+C19 | O19: =IF(OR(L19=0,H19>NoEchMaxi),0,ROUND(FraisF+FraisV*L19,NbDeci))+F19 | P19: =SUM(M19:O19) | R19: =IF(B19>0,IF(TauxActuariel,((B19+1)^(1/NbEchAn))-1,B19/NbEchAn),R18) | S19: =IF(E19>0,E19,IF(D19>0,IF(AND(EchFIXE,R19>0),ROUND((L19-C19)*R19/(1-((1+R19)^-D19)),NbDeci),ROUND(L19/D19,NbDeci)),S18))
H20: =IF(L20=0,"",H19+1) | I20: =IF(L20>0,NbEch+Différé+1-H20,"") | J20: =IF(ISNUMBER(K20),YEAR(K20),"") | K20: =IF(L20=0,"",IF(Ijour=0,MIN(DATE(YEAR(DebAmort),MONTH(DebAmort)+MoisD+(H20-1)*Imois,Jour2),DATE(YEAR(DebAmort),MONTH(DebAmort)+MoisD+1+(H20-1)*Imois,0)),DATE(YEAR(DebAmort),MONTH(DebAmort),Jour1+(H20-1)*Ijour))) | L20: =L19-N19 | M20: =IF(H20<=NoEchMaxi,ROUND(L20*R20,NbDeci),0) | N20: =IF(OR(H20<=Différé,H20>NoEchMaxi),IF(DiffTotal,-M20,0),IF(H20>=NoEchRemb,L20,IF(S20-(M20*EchFIXE)>L20-2,L20,S20-(M20*EchFIXE))))+C20 | O20: =IF(OR(L20=0,H20>NoEchMaxi),0,ROUND(FraisF+FraisV*L20,NbDeci))+F20 | P20: =SUM(M20:O20) | R20: =IF(B20>0,IF(TauxActuariel,((B20+1)^(1/NbEchAn))-1,B20/NbEchAn),R19) | S20: =IF(E20>0,E20,IF(D20>0,IF(AND(EchFIXE,R20>0),ROUND((L20-C20)*R20/(1-((1+R20)^-D20)),NbDeci),ROUND(L20/D20,NbDeci)),S19))
H21: =IF(L21=0,"",H20+1) | I21: =IF(L21>0,NbEch+Différé+1-H21,"") | J21: =IF(ISNUMBER(K21),YEAR(K21),"") | K21: =IF(L21=0,"",IF(Ijour=0,MIN(DATE(YEAR(DebAmort),MONTH(DebAmort)+(H21-1)*Imois,Jour1),DATE(YEAR(DebAmort),MONTH(DebAmort)+1+(H21-1)*Imois,0)),DATE(YEAR(DebAmort),MONTH(DebAmort),Jour1+(H21-1)*Ijour))) | L21: =L20-N20 | M21: =IF(H21<=NoEchMaxi,ROUND(L21*R21,NbDeci),0) | N21: =IF(OR(H21<=Différé,H21>NoEchMaxi),IF(DiffTotal,-M21,0),IF(H21>=NoEchRemb,L21,IF(S21-(M21*EchFIXE)>L21-2,L21,S21-(M21*EchFIXE))))+C21 | O21: =IF(OR(L21=0,H21>NoEchMaxi),0,ROUND(FraisF+FraisV*L21,NbDeci))+F21 | P21: =SUM(M21:O21) | R21: =IF(B21>0,IF(TauxActuariel,((B21+1)^(1/NbEchAn))-1,B21/NbEchAn),R20) | S21: =IF(E21>0,E21,IF(D21>0,IF(AND(EchFIXE,R21>0),ROUND((L21-C21)*R21/(1-((1+R21)^-D21)),NbDeci),ROUND(L21/D21,NbDeci)),S20))
H22: =IF(L22=0,"",H21+1) | I22: =IF(L22>0,NbEch+Différé+1-H22,"") | J22: =IF(ISNUMBER(K22),YEAR(K22),"") | K22: =IF(L22=0,"",IF(Ijour=0,MIN(DATE(YEAR(DebAmort),MONTH(DebAmort)+MoisD+(H22-1)*Imois,Jour2),DATE(YEAR(DebAmort),MONTH(DebAmort)+MoisD+1+(H22-1)*Imois,0)),DATE(YEAR(DebAmort),MONTH(DebAmort),Jour1+(H22-1)*Ijour))) | L22: =L21-N21 | M22: =IF(H22<=NoEchMaxi,ROUND(L22*R22,NbDeci),0) | N22: =IF(OR(H22<=Différé,H22>NoEchMaxi),IF(DiffTotal,-M22,0),IF(H22>=NoEchRemb,L22,IF(S22-(M22*EchFIXE)>L22-2,L22,S22-(M22*EchFIXE))))+C22 | O22: =IF(OR(L22=0,H22>NoEchMaxi),0,ROUND(FraisF+FraisV*L22,NbDeci))+F22 | P22: =SUM(M22:O22) | R22: =IF(B22>0,IF(TauxActuariel,((B22+1)^(1/NbEchAn))-1,B22/NbEchAn),R21) | S22: =IF(E22>0,E22,IF(D22>0,IF(AND(EchFIXE,R22>0),ROUND((L22-C22)*R22/(1-((1+R22)^-D22)),NbDeci),ROUND(L22/D22,NbDeci)),S21))
H23: =IF(L23=0,"",H22+1) | I23: =IF(L23>0,NbEch+Différé+1-H23,"") | J23: =IF(ISNUMBER(K23),YEAR(K23),"") | K23: =IF(L23=0,"",IF(Ijour=0,MIN(DATE(YEAR(DebAmort),MONTH(DebAmort)+(H23-1)*Imois,Jour1),DATE(YEAR(DebAmort),MONTH(DebAmort)+1+(H23-1)*Imois,0)),DATE(YEAR(DebAmort),MONTH(DebAmort),Jour1+(H23-1)*Ijour))) | L23: =L22-N22 | M23: =IF(H23<=NoEchMaxi,ROUND(L23*R23,NbDeci),0) | N23: =IF(OR(H23<=Différé,H23>NoEchMaxi),IF(DiffTotal,-M23,0),IF(H23>=NoEchRemb,L23,IF(S23-(M23*EchFIXE)>L23-2,L23,S23-(M23*EchFIXE))))+C23 | O23: =IF(OR(L23=0,H23>NoEchMaxi),0,ROUND(FraisF+FraisV*L23,NbDeci))+F23 | P23: =SUM(M23:O23) | R23: =IF(B23>0,IF(TauxActuariel,((B23+1)^(1/NbEchAn))-1,B23/NbEchAn),R22) | S23: =IF(E23>0,E23,IF(D23>0,IF(AND(EchFIXE,R23>0),ROUND((L23-C23)*R23/(1-((1+R23)^-D23)),NbDeci),ROUND(L23/D23,NbDeci)),S22))
H24: =IF(L24=0,"",H23+1) | I24: =IF(L24>0,NbEch+Différé+1-H24,"") | J24: =IF(ISNUMBER(K24),YEAR(K24),"") | K24: =IF(L24=0,"",IF(Ijour=0,MIN(DATE(YEAR(DebAmort),MONTH(DebAmort)+MoisD+(H24-1)*Imois,Jour2),DATE(YEAR(DebAmort),MONTH(DebAmort)+MoisD+1+(H24-1)*Imois,0)),DATE(YEAR(DebAmort),MONTH(DebAmort),Jour1+(H24-1)*Ijour))) | L24: =L23-N23 | M24: =IF(H24<=NoEchMaxi,ROUND(L24*R24,NbDeci),0) | N24: =IF(OR(H24<=Différé,H24>NoEchMaxi),IF(DiffTotal,-M24,0),IF(H24>=NoEchRemb,L24,IF(S24-(M24*EchFIXE)>L24-2,L24,S24-(M24*EchFIXE))))+C24 | O24: =IF(OR(L24=0,H24>NoEchMaxi),0,ROUND(FraisF+FraisV*L24,NbDeci))+F24 | P24: =SUM(M24:O24) | R24: =IF(B24>0,IF(TauxActuariel,((B24+1)^(1/NbEchAn))-1,B24/NbEchAn),R23) | S24: =IF(E24>0,E24,IF(D24>0,IF(AND(EchFIXE,R24>0),ROUND((L24-C24)*R24/(1-((1+R24)^-D24)),NbDeci),ROUND(L24/D24,NbDeci)),S23))
H25: =IF(L25=0,"",H24+1) | I25: =IF(L25>0,NbEch+Différé+1-H25,"") | J25: =IF(ISNUMBER(K25),YEAR(K25),"") | K25: =IF(L25=0,"",IF(Ijour=0,MIN(DATE(YEAR(DebAmort),MONTH(DebAmort)+(H25-1)*Imois,Jour1),DATE(YEAR(DebAmort),MONTH(DebAmort)+1+(H25-1)*Imois,0)),DATE(YEAR(DebAmort),MONTH(DebAmort),Jour1+(H25-1)*Ijour))) | L25: =L24-N24 | M25: =IF(H25<=NoEchMaxi,ROUND(L25*R25,NbDeci),0) | N25: =IF(OR(H25<=Différé,H25>NoEchMaxi),IF(DiffTotal,-M25,0),IF(H25>=NoEchRemb,L25,IF(S25-(M25*EchFIXE)>L25-2,L25,S25-(M25*EchFIXE))))+C25 | O25: =IF(OR(L25=0,H25>NoEchMaxi),0,ROUND(FraisF+FraisV*L25,NbDeci))+F25 | P25: =SUM(M25:O25) | R25: =IF(B25>0,IF(TauxActuariel,((B25+1)^(1/NbEchAn))-1,B25/NbEchAn),R24) | S25: =IF(E25>0,E25,IF(D25>0,IF(AND(EchFIXE,R25>0),ROUND((L25-C25)*R25/(1-((1+R25)^-D25)),NbDeci),ROUND(L25/D25,NbDeci)),S24))
H26: =IF(L26=0,"",H25+1) | I26: =IF(L26>0,NbEch+Différé+1-H26,"") | J26: =IF(ISNUMBER(K26),YEAR(K26),"") | K26: =IF(L26=0,"",IF(Ijour=0,MIN(DATE(YEAR(DebAmort),MONTH(DebAmort)+MoisD+(H26-1)*Imois,Jour2),DATE(YEAR(DebAmort),MONTH(DebAmort)+MoisD+1+(H26-1)*Imois,0)),DATE(YEAR(DebAmort),MONTH(DebAmort),Jour1+(H26-1)*Ijour))) | L26: =L25-N25 | M26: =IF(H26<=NoEchMaxi,ROUND(L26*R26,NbDeci),0) | N26: =IF(OR(H26<=Différé,H26>NoEchMaxi),IF(DiffTotal,-M26,0),IF(H26>=NoEchRemb,L26,IF(S26-(M26*EchFIXE)>L26-2,L26,S26-(M26*EchFIXE))))+C26 | O26: =IF(OR(L26=0,H26>NoEchMaxi),0,ROUND(FraisF+FraisV*L26,NbDeci))+F26 | P26: =SUM(M26:O26) | R26: =IF(B26>0,IF(TauxActuariel,((B26+1)^(1/NbEchAn))-1,B26/NbEchAn),R25) | S26: =IF(E26>0,E26,IF(D26>0,IF(AND(EchFIXE,R26>0),ROUND((L26-C26)*R26/(1-((1+R26)^-D26)),NbDeci),ROUND(L26/D26,NbDeci)),S25))
H27: =IF(L27=0,"",H26+1) | I27: =IF(L27>0,NbEch+Différé+1-H27,"") | J27: =IF(ISNUMBER(K27),YEAR(K27),"") | K27: =IF(L27=0,"",IF(Ijour=0,MIN(DATE(YEAR(DebAmort),MONTH(DebAmort)+(H27-1)*Imois,Jour1),DATE(YEAR(DebAmort),MONTH(DebAmort)+1+(H27-1)*Imois,0)),DATE(YEAR(DebAmort),MONTH(DebAmort),Jour1+(H27-1)*Ijour))) | L27: =L26-N26 | M27: =IF(H27<=NoEchMaxi,ROUND(L27*R27,NbDeci),0) | N27: =IF(OR(H27<=Différé,H27>NoEchMaxi),IF(DiffTotal,-M27,0),IF(H27>=NoEchRemb,L27,IF(S27-(M27*EchFIXE)>L27-2,L27,S27-(M27*EchFIXE))))+C27 | O27: =IF(OR(L27=0,H27>NoEchMaxi),0,ROUND(FraisF+FraisV*L27,NbDeci))+F27 | P27: =SUM(M27:O27) | R27: =IF(B27>0,IF(TauxActuariel,((B27+1)^(1/NbEchAn))-1,B27/NbEchAn),R26) | S27: =IF(E27>0,E27,IF(D27>0,IF(AND(EchFIXE,R27>0),ROUND((L27-C27)*R27/(1-((1+R27)^-D27)),NbDeci),ROUND(L27/D27,NbDeci)),S26))
H28: =IF(L28=0,"",H27+1) | I28: =IF(L28>0,NbEch+Différé+1-H28,"") | J28: =IF(ISNUMBER(K28),YEAR(K28),"") | K28: =IF(L28=0,"",IF(Ijour=0,MIN(DATE(YEAR(DebAmort),MONTH(DebAmort)+MoisD+(H28-1)*Imois,Jour2),DATE(YEAR(DebAmort),MONTH(DebAmort)+MoisD+1+(H28-1)*Imois,0)),DATE(YEAR(DebAmort),MONTH(DebAmort),Jour1+(H28-1)*Ijour))) | L28: =L27-N27 | M28: =IF(H28<=NoEchMaxi,ROUND(L28*R28,NbDeci),0) | N28: =IF(OR(H28<=Différé,H28>NoEchMaxi),IF(DiffTotal,-M28,0),IF(H28>=NoEchRemb,L28,IF(S28-(M28*EchFIXE)>L28-2,L28,S28-(M28*EchFIXE))))+C28 | O28: =IF(OR(L28=0,H28>NoEchMaxi),0,ROUND(FraisF+FraisV*L28,NbDeci))+F28 | P28: =SUM(M28:O28) | R28: =IF(B28>0,IF(TauxActuariel,((B28+1)^(1/NbEchAn))-1,B28/NbEchAn),R27) | S28: =IF(E28>0,E28,IF(D28>0,IF(AND(EchFIXE,R28>0),ROUND((L28-C28)*R28/(1-((1+R28)^-D28)),NbDeci),ROUND(L28/D28,NbDeci)),S27))
H29: =IF(L29=0,"",H28+1) | I29: =IF(L29>0,NbEch+Différé+1-H29,"") | J29: =IF(ISNUMBER(K29),YEAR(K29),"") | K29: =IF(L29=0,"",IF(Ijour=0,MIN(DATE(YEAR(DebAmort),MONTH(DebAmort)+(H29-1)*Imois,Jour1),DATE(YEAR(DebAmort),MONTH(DebAmort)+1+(H29-1)*Imois,0)),DATE(YEAR(DebAmort),MONTH(DebAmort),Jour1+(H29-1)*Ijour))) | L29: =L28-N28 | M29: =IF(H29<=NoEchMaxi,ROUND(L29*R29,NbDeci),0) | N29: =IF(OR(H29<=Différé,H29>NoEchMaxi),IF(DiffTotal,-M29,0),IF(H29>=NoEchRemb,L29,IF(S29-(M29*EchFIXE)>L29-2,L29,S29-(M29*EchFIXE))))+C29 | O29: =IF(OR(L29=0,H29>NoEchMaxi),0,ROUND(FraisF+FraisV*L29,NbDeci))+F29 | P29: =SUM(M29:O29) | R29: =IF(B29>0,IF(TauxActuariel,((B29+1)^(1/NbEchAn))-1,B29/NbEchAn),R28) | S29: =IF(E29>0,E29,IF(D29>0,IF(AND(EchFIXE,R29>0),ROUND((L29-C29)*R29/(1-((1+R29)^-D29)),NbDeci),ROUND(L29/D29,NbDeci)),S28))
H30: =IF(L30=0,"",H29+1) | I30: =IF(L30>0,NbEch+Différé+1-H30,"") | J30: =IF(ISNUMBER(K30),YEAR(K30),"") | K30: =IF(L30=0,"",IF(Ijour=0,MIN(DATE(YEAR(DebAmort),MONTH(DebAmort)+MoisD+(H30-1)*Imois,Jour2),DATE(YEAR(DebAmort),MONTH(DebAmort)+MoisD+1+(H30-1)*Imois,0)),DATE(YEAR(DebAmort),MONTH(DebAmort),Jour1+(H30-1)*Ijour))) | L30: =L29-N29 | M30: =IF(H30<=NoEchMaxi,ROUND(L30*R30,NbDeci),0) | N30: =IF(OR(H30<=Différé,H30>NoEchMaxi),IF(DiffTotal,-M30,0),IF(H30>=NoEchRemb,L30,IF(S30-(M30*EchFIXE)>L30-2,L30,S30-(M30*EchFIXE))))+C30 | O30: =IF(OR(L30=0,H30>NoEchMaxi),0,ROUND(FraisF+FraisV*L30,NbDeci))+F30 | P30: =SUM(M30:O30) | R30: =IF(B30>0,IF(TauxActuariel,((B30+1)^(1/NbEchAn))-1,B30/NbEchAn),R29) | S30: =IF(E30>0,E30,IF(D30>0,IF(AND(EchFIXE,R30>0),ROUND((L30-C30)*R30/(1-((1+R30)^-D30)),NbDeci),ROUND(L30/D30,NbDeci)),S29))
H31: =IF(L31=0,"",H30+1) | I31: =IF(L31>0,NbEch+Différé+1-H31,"") | J31: =IF(ISNUMBER(K31),YEAR(K31),"") | K31: =IF(L31=0,"",IF(Ijour=0,MIN(DATE(YEAR(DebAmort),MONTH(DebAmort)+(H31-1)*Imois,Jour1),DATE(YEAR(DebAmort),MONTH(DebAmort)+1+(H31-1)*Imois,0)),DATE(YEAR(DebAmort),MONTH(DebAmort),Jour1+(H31-1)*Ijour))) | L31: =L30-N30 | M31: =IF(H31<=NoEchMaxi,ROUND(L31*R31,NbDeci),0) | N31: =IF(OR(H31<=Différé,H31>NoEchMaxi),IF(DiffTotal,-M31,0),IF(H31>=NoEchRemb,L31,IF(S31-(M31*EchFIXE)>L31-2,L31,S31-(M31*EchFIXE))))+C31 | O31: =IF(OR(L31=0,H31>NoEchMaxi),0,ROUND(FraisF+FraisV*L31,NbDeci))+F31 | P31: =SUM(M31:O31) | R31: =IF(B31>0,IF(TauxActuariel,((B31+1)^(1/NbEchAn))-1,B31/NbEchAn),R30) | S31: =IF(E31>0,E31,IF(D31>0,IF(AND(EchFIXE,R31>0),ROUND((L31-C31)*R31/(1-((1+R31)^-D31)),NbDeci),ROUND(L31/D31,NbDeci)),S30))
H32: =IF(L32=0,"",H31+1) | I32: =IF(L32>0,NbEch+Différé+1-H32,"") | J32: =IF(ISNUMBER(K32),YEAR(K32),"") | K32: =IF(L32=0,"",IF(Ijour=0,MIN(DATE(YEAR(DebAmort),MONTH(DebAmort)+MoisD+(H32-1)*Imois,Jour2),DATE(YEAR(DebAmort),MONTH(DebAmort)+MoisD+1+(H32-1)*Imois,0)),DATE(YEAR(DebAmort),MONTH(DebAmort),Jour1+(H32-1)*Ijour))) | L32: =L31-N31 | M32: =IF(H32<=NoEchMaxi,ROUND(L32*R32,NbDeci),0) | N32: =IF(OR(H32<=Différé,H32>NoEchMaxi),IF(DiffTotal,-M32,0),IF(H32>=NoEchRemb,L32,IF(S32-(M32*EchFIXE)>L32-2,L32,S32-(M32*EchFIXE))))+C32 | O32: =IF(OR(L32=0,H32>NoEchMaxi),0,ROUND(FraisF+FraisV*L32,NbDeci))+F32 | P32: =SUM(M32:O32) | R32: =IF(B32>0,IF(TauxActuariel,((B32+1)^(1/NbEchAn))-1,B32/NbEchAn),R31) | S32: =IF(E32>0,E32,IF(D32>0,IF(AND(EchFIXE,R32>0),ROUND((L32-C32)*R32/(1-((1+R32)^-D32)),NbDeci),ROUND(L32/D32,NbDeci)),S31))
H33: =IF(L33=0,"",H32+1) | I33: =IF(L33>0,NbEch+Différé+1-H33,"") | J33: =IF(ISNUMBER(K33),YEAR(K33),"") | K33: =IF(L33=0,"",IF(Ijour=0,MIN(DATE(YEAR(DebAmort),MONTH(DebAmort)+(H33-1)*Imois,Jour1),DATE(YEAR(DebAmort),MONTH(DebAmort)+1+(H33-1)*Imois,0)),DATE(YEAR(DebAmort),MONTH(DebAmort),Jour1+(H33-1)*Ijour))) | L33: =L32-N32 | M33: =IF(H33<=NoEchMaxi,ROUND(L33*R33,NbDeci),0) | N33: =IF(OR(H33<=Différé,H33>NoEchMaxi),IF(DiffTotal,-M33,0),IF(H33>=NoEchRemb,L33,IF(S33-(M33*EchFIXE)>L33-2,L33,S33-(M33*EchFIXE))))+C33 | O33: =IF(OR(L33=0,H33>NoEchMaxi),0,ROUND(FraisF+FraisV*L33,NbDeci))+F33 | P33: =SUM(M33:O33) | R33: =IF(B33>0,IF(TauxActuariel,((B33+1)^(1/NbEchAn))-1,B33/NbEchAn),R32) | S33: =IF(E33>0,E33,IF(D33>0,IF(AND(EchFIXE,R33>0),ROUND((L33-C33)*R33/(1-((1+R33)^-D33)),NbDeci),ROUND(L33/D33,NbDeci)),S32))
H34: =IF(L34=0,"",H33+1) | I34: =IF(L34>0,NbEch+Différé+1-H34,"") | J34: =IF(ISNUMBER(K34),YEAR(K34),"") | K34: =IF(L34=0,"",IF(Ijour=0,MIN(DATE(YEAR(DebAmort),MONTH(DebAmort)+MoisD+(H34-1)*Imois,Jour2),DATE(YEAR(DebAmort),MONTH(DebAmort)+MoisD+1+(H34-1)*Imois,0)),DATE(YEAR(DebAmort),MONTH(DebAmort),Jour1+(H34-1)*Ijour))) | L34: =L33-N33 | M34: =IF(H34<=NoEchMaxi,ROUND(L34*R34,NbDeci),0) | N34: =IF(OR(H34<=Différé,H34>NoEchMaxi),IF(DiffTotal,-M34,0),IF(H34>=NoEchRemb,L34,IF(S34-(M34*EchFIXE)>L34-2,L34,S34-(M34*EchFIXE))))+C34 | O34: =IF(OR(L34=0,H34>NoEchMaxi),0,ROUND(FraisF+FraisV*L34,NbDeci))+F34 | P34: =SUM(M34:O34) | R34: =IF(B34>0,IF(TauxActuariel,((B34+1)^(1/NbEchAn))-1,B34/NbEchAn),R33) | S34: =IF(E34>0,E34,IF(D34>0,IF(AND(EchFIXE,R34>0),ROUND((L34-C34)*R34/(1-((1+R34)^-D34)),NbDeci),ROUND(L34/D34,NbDeci)),S33))
H35: =IF(L35=0,"",H34+1) | I35: =IF(L35>0,NbEch+Différé+1-H35,"") | J35: =IF(ISNUMBER(K35),YEAR(K35),"") | K35: =IF(L35=0,"",IF(Ijour=0,MIN(DATE(YEAR(DebAmort),MONTH(DebAmort)+(H35-1)*Imois,Jour1),DATE(YEAR(DebAmort),MONTH(DebAmort)+1+(H35-1)*Imois,0)),DATE(YEAR(DebAmort),MONTH(DebAmort),Jour1+(H35-1)*Ijour))) | L35: =L34-N34 | M35: =IF(H35<=NoEchMaxi,ROUND(L35*R35,NbDeci),0) | N35: =IF(OR(H35<=Différé,H35>NoEchMaxi),IF(DiffTotal,-M35,0),IF(H35>=NoEchRemb,L35,IF(S35-(M35*EchFIXE)>L35-2,L35,S35-(M35*EchFIXE))))+C35 | O35: =IF(OR(L35=0,H35>NoEchMaxi),0,ROUND(FraisF+FraisV*L35,NbDeci))+F35 | P35: =SUM(M35:O35) | R35: =IF(B35>0,IF(TauxActuariel,((B35+1)^(1/NbEchAn))-1,B35/NbEchAn),R34) | S35: =IF(E35>0,E35,IF(D35>0,IF(AND(EchFIXE,R35>0),ROUND((L35-C35)*R35/(1-((1+R35)^-D35)),NbDeci),ROUND(L35/D35,NbDeci)),S34))
H36: =IF(L36=0,"",H35+1) | I36: =IF(L36>0,NbEch+Différé+1-H36,"") | J36: =IF(ISNUMBER(K36),YEAR(K36),"") | K36: =IF(L36=0,"",IF(Ijour=0,MIN(DATE(YEAR(DebAmort),MONTH(DebAmort)+MoisD+(H36-1)*Imois,Jour2),DATE(YEAR(DebAmort),MONTH(DebAmort)+MoisD+1+(H36-1)*Imois,0)),DATE(YEAR(DebAmort),MONTH(DebAmort),Jour1+(H36-1)*Ijour))) | L36: =L35-N35 | M36: =IF(H36<=NoEchMaxi,ROUND(L36*R36,NbDeci),0) | N36: =IF(OR(H36<=Différé,H36>NoEchMaxi),IF(DiffTotal,-M36,0),IF(H36>=NoEchRemb,L36,IF(S36-(M36*EchFIXE)>L36-2,L36,S36-(M36*EchFIXE))))+C36 | O36: =IF(OR(L36=0,H36>NoEchMaxi),0,ROUND(FraisF+FraisV*L36,NbDeci))+F36 | P36: =SUM(M36:O36) | R36: =IF(B36>0,IF(TauxActuariel,((B36+1)^(1/NbEchAn))-1,B36/NbEchAn),R35) | S36: =IF(E36>0,E36,IF(D36>0,IF(AND(EchFIXE,R36>0),ROUND((L36-C36)*R36/(1-((1+R36)^-D36)),NbDeci),ROUND(L36/D36,NbDeci)),S35))
H37: =IF(L37=0,"",H36+1) | I37: =IF(L37>0,NbEch+Différé+1-H37,"") | J37: =IF(ISNUMBER(K37),YEAR(K37),"") | K37: =IF(L37=0,"",IF(Ijour=0,MIN(DATE(YEAR(DebAmort),MONTH(DebAmort)+(H37-1)*Imois,Jour1),DATE(YEAR(DebAmort),MONTH(DebAmort)+1+(H37-1)*Imois,0)),DATE(YEAR(DebAmort),MONTH(DebAmort),Jour1+(H37-1)*Ijour))) | L37: =L36-N36 | M37: =IF(H37<=NoEchMaxi,ROUND(L37*R37,NbDeci),0) | N37: =IF(OR(H37<=Différé,H37>NoEchMaxi),IF(DiffTotal,-M37,0),IF(H37>=NoEchRemb,L37,IF(S37-(M37*EchFIXE)>L37-2,L37,S37-(M37*EchFIXE))))+C37 | O37: =IF(OR(L37=0,H37>NoEchMaxi),0,ROUND(FraisF+FraisV*L37,NbDeci))+F37 | P37: =SUM(M37:O37) | R37: =IF(B37>0,IF(TauxActuariel,((B37+1)^(1/NbEchAn))-1,B37/NbEchAn),R36) | S37: =IF(E37>0,E37,IF(D37>0,IF(AND(EchFIXE,R37>0),ROUND((L37-C37)*R37/(1-((1+R37)^-D37)),NbDeci),ROUND(L37/D37,NbDeci)),S36))
H38: =IF(L38=0,"",H37+1) | I38: =IF(L38>0,NbEch+Différé+1-H38,"") | J38: =IF(ISNUMBER(K38),YEAR(K38),"") | K38: =IF(L38=0,"",IF(Ijour=0,MIN(DATE(YEAR(DebAmort),MONTH(DebAmort)+MoisD+(H38-1)*Imois,Jour2),DATE(YEAR(DebAmort),MONTH(DebAmort)+MoisD+1+(H38-1)*Imois,0)),DATE(YEAR(DebAmort),MONTH(DebAmort),Jour1+(H38-1)*Ijour))) | L38: =L37-N37 | M38: =IF(H38<=NoEchMaxi,ROUND(L38*R38,NbDeci),0) | N38: =IF(OR(H38<=Différé,H38>NoEchMaxi),IF(DiffTotal,-M38,0),IF(H38>=NoEchRemb,L38,IF(S38-(M38*EchFIXE)>L38-2,L38,S38-(M38*EchFIXE))))+C38 | O38: =IF(OR(L38=0,H38>NoEchMaxi),0,ROUND(FraisF+FraisV*L38,NbDeci))+F38 | P38: =SUM(M38:O38) | R38: =IF(B38>0,IF(TauxActuariel,((B38+1)^(1/NbEchAn))-1,B38/NbEchAn),R37) | S38: =IF(E38>0,E38,IF(D38>0,IF(AND(EchFIXE,R38>0),ROUND((L38-C38)*R38/(1-((1+R38)^-D38)),NbDeci),ROUND(L38/D38,NbDeci)),S37))
H39: =IF(L39=0,"",H38+1) | I39: =IF(L39>0,NbEch+Différé+1-H39,"") | J39: =IF(ISNUMBER(K39),YEAR(K39),"") | K39: =IF(L39=0,"",IF(Ijour=0,MIN(DATE(YEAR(DebAmort),MONTH(DebAmort)+(H39-1)*Imois,Jour1),DATE(YEAR(DebAmort),MONTH(DebAmort)+1+(H39-1)*Imois,0)),DATE(YEAR(DebAmort),MONTH(DebAmort),Jour1+(H39-1)*Ijour))) | L39: =L38-N38 | M39: =IF(H39<=NoEchMaxi,ROUND(L39*R39,NbDeci),0) | N39: =IF(OR(H39<=Différé,H39>NoEchMaxi),IF(DiffTotal,-M39,0),IF(H39>=NoEchRemb,L39,IF(S39-(M39*EchFIXE)>L39-2,L39,S39-(M39*EchFIXE))))+C39 | O39: =IF(OR(L39=0,H39>NoEchMaxi),0,ROUND(FraisF+FraisV*L39,NbDeci))+F39 | P39: =SUM(M39:O39) | R39: =IF(B39>0,IF(TauxActuariel,((B39+1)^(1/NbEchAn))-1,B39/NbEchAn),R38) | S39: =IF(E39>0,E39,IF(D39>0,IF(AND(EchFIXE,R39>0),ROUND((L39-C39)*R39/(1-((1+R39)^-D39)),NbDeci),ROUND(L39/D39,NbDeci)),S38))
H40: =IF(L40=0,"",H39+1) | I40: =IF(L40>0,NbEch+Différé+1-H40,"") | J40: =IF(ISNUMBER(K40),YEAR(K40),"") | K40: =IF(L40=0,"",IF(Ijour=0,MIN(DATE(YEAR(DebAmort),MONTH(DebAmort)+MoisD+(H40-1)*Imois,Jour2),DATE(YEAR(DebAmort),MONTH(DebAmort)+MoisD+1+(H40-1)*Imois,0)),DATE(YEAR(DebAmort),MONTH(DebAmort),Jour1+(H40-1)*Ijour))) | L40: =L39-N39 | M40: =IF(H40<=NoEchMaxi,ROUND(L40*R40,NbDeci),0) | N40: =IF(OR(H40<=Différé,H40>NoEchMaxi),IF(DiffTotal,-M40,0),IF(H40>=NoEchRemb,L40,IF(S40-(M40*EchFIXE)>L40-2,L40,S40-(M40*EchFIXE))))+C40 | O40: =IF(OR(L40=0,H40>NoEchMaxi),0,ROUND(FraisF+FraisV*L40,NbDeci))+F40 | P40: =SUM(M40:O40) | R40: =IF(B40>0,IF(TauxActuariel,((B40+1)^(1/NbEchAn))-1,B40/NbEchAn),R39) | S40: =IF(E40>0,E40,IF(D40>0,IF(AND(EchFIXE,R40>0),ROUND((L40-C40)*R40/(1-((1+R40)^-D40)),NbDeci),ROUND(L40/D40,NbDeci)),S39))
...

Sheet Avancé
I1: Colonne
B2: Décimalisation de la monnaie | I2: Non
B3: Nombre de décimales | D3: 3 | I3: Verouillé
I4: (A CACHER)
B5: Type d'amortissement
I9: 1
B11: Limitation de l'amortissement
I12: FALSE
C14: à | E14: an(s) et / ou | G14: mois
I15: FALSE
D17: =IF(I12=TRUE,(D14*12+F14)*NbEchAn/12,99999) | E17: =IF(AND(I12,I15),(D14*12+F14)*NbEchAn/12,99999)
B19: Calcul première échéance
B21: Date première échéance : | D21: =DebAmort
B22: Date déblocage théorique : | D22: =IF(Ijour=0,MIN(DATE(YEAR(DebAmort),MONTH(DebAmort)-MoisD-Imois,Jour2),DATE(YEAR(DebAmort),MONTH(DebAmort)-MoisD+1-Imois,0)),DATE(YEAR(DebAmort),MONTH(DebAmort),Jour1-Ijour)) | E22: =" (Durée période : "&F37&" jours)"
B23: Date déblocage réel : | D23: =D22+I23-500 | E23: =" (Durée période : "&G37&" jours)" | I23: 500
I27: 1
D32: -1- | E32: -2- | F32: -3-
B33: Date déblocage fonds : | D33: =D22 | E33: =D23 | F33: =D23
B34: Montant des Intérêts : | D34: =ROUND(TAM!L15*TAM!R15,NbDeci) | E34: =IF(TauxActuariel, ROUND(TAM!L15*(((TAM!D5+1)^(G37/365))-1),NbDeci), ROUND(TAM!L15*(TAM!D5*G37/365),NbDeci))
B35: Montant du capital : | D35: =IF(1<=Différé,IF(DiffTotal,-D34,0),TAM!S15-(D34*EchFIXE)) | E35: =IF(AND(1<=Différé,DiffTotal),-E34,D35)
B36: Total échéance (hors frais) : | D36: =D34+D35 | E36: =E34+E35 | F36: =F34+F35
C37: =IF(I27=1,D22,D23) | D37: =IF(I27=1,D34)+IF(I27=2,E34)+IF(I27=3,F34) | E37: =IF(I27=1,D35)+IF(I27=2,E35)+IF(I27=3,F35) | F37: =D21-D22 | G37: =D21-D23
